2018-03-25 23:47:47,592 ERROR: Exception on /index [GET] [in /home/ari/Documents/LastChance/microblog/mb_venv/lib/python3.5/site-packages/flask/app.py: 1560]
Traceback (most recent call last):
  File "/home/ari/Documents/LastChance/microblog/mb_venv/lib/python3.5/site-packages/flask/app.py", line 1982, in wsgi_app
    response = self.full_dispatch_request()
  File "/home/ari/Documents/LastChance/microblog/mb_venv/lib/python3.5/site-packages/flask/app.py", line 1614, in full_dispatch_request
    rv = self.handle_user_exception(e)
  File "/home/ari/Documents/LastChance/microblog/mb_venv/lib/python3.5/site-packages/flask/app.py", line 1517, in handle_user_exception
    reraise(exc_type, exc_value, tb)
  File "/home/ari/Documents/LastChance/microblog/mb_venv/lib/python3.5/site-packages/flask/_compat.py", line 33, in reraise
    raise value
  File "/home/ari/Documents/LastChance/microblog/mb_venv/lib/python3.5/site-packages/flask/app.py", line 1612, in full_dispatch_request
    rv = self.dispatch_request()
  File "/home/ari/Documents/LastChance/microblog/mb_venv/lib/python3.5/site-packages/flask/app.py", line 1598, in dispatch_request
    return self.view_functions[rule.endpoint](**req.view_args)
  File "/home/ari/Documents/LastChance/microblog/mb_venv/lib/python3.5/site-packages/flask_login/utils.py", line 261, in decorated_view
    return func(*args, **kwargs)
  File "/home/ari/Documents/LastChance/microblog/app/routes.py", line 81, in index
    posts = posts.items, next_url=next_url, prev_url=prev_url)
AttributeError: 'list' object has no attribute 'items'
2018-03-25 23:47:48,657 ERROR: Exception on /index [GET] [in /home/ari/Documents/LastChance/microblog/mb_venv/lib/python3.5/site-packages/flask/app.py: 1560]
Traceback (most recent call last):
  File "/home/ari/Documents/LastChance/microblog/mb_venv/lib/python3.5/site-packages/flask/app.py", line 1982, in wsgi_app
    response = self.full_dispatch_request()
  File "/home/ari/Documents/LastChance/microblog/mb_venv/lib/python3.5/site-packages/flask/app.py", line 1614, in full_dispatch_request
    rv = self.handle_user_exception(e)
  File "/home/ari/Documents/LastChance/microblog/mb_venv/lib/python3.5/site-packages/flask/app.py", line 1517, in handle_user_exception
    reraise(exc_type, exc_value, tb)
  File "/home/ari/Documents/LastChance/microblog/mb_venv/lib/python3.5/site-packages/flask/_compat.py", line 33, in reraise
    raise value
  File "/home/ari/Documents/LastChance/microblog/mb_venv/lib/python3.5/site-packages/flask/app.py", line 1612, in full_dispatch_request
    rv = self.dispatch_request()
  File "/home/ari/Documents/LastChance/microblog/mb_venv/lib/python3.5/site-packages/flask/app.py", line 1598, in dispatch_request
    return self.view_functions[rule.endpoint](**req.view_args)
  File "/home/ari/Documents/LastChance/microblog/mb_venv/lib/python3.5/site-packages/flask_login/utils.py", line 261, in decorated_view
    return func(*args, **kwargs)
  File "/home/ari/Documents/LastChance/microblog/app/routes.py", line 81, in index
    posts = posts.items, next_url=next_url, prev_url=prev_url)
AttributeError: 'list' object has no attribute 'items'
2018-03-26 21:13:39,059 INFO: Microblog startup [in /home/ari/Documents/LastChance/microblog/app/__init__.py: 49]
2018-03-26 21:14:01,680 ERROR: Exception on /index [GET] [in /home/ari/Documents/LastChance/microblog/mb_venv/lib/python3.5/site-packages/flask/app.py: 1560]
Traceback (most recent call last):
  File "/home/ari/Documents/LastChance/microblog/mb_venv/lib/python3.5/site-packages/flask/app.py", line 1982, in wsgi_app
    response = self.full_dispatch_request()
  File "/home/ari/Documents/LastChance/microblog/mb_venv/lib/python3.5/site-packages/flask/app.py", line 1614, in full_dispatch_request
    rv = self.handle_user_exception(e)
  File "/home/ari/Documents/LastChance/microblog/mb_venv/lib/python3.5/site-packages/flask/app.py", line 1517, in handle_user_exception
    reraise(exc_type, exc_value, tb)
  File "/home/ari/Documents/LastChance/microblog/mb_venv/lib/python3.5/site-packages/flask/_compat.py", line 33, in reraise
    raise value
  File "/home/ari/Documents/LastChance/microblog/mb_venv/lib/python3.5/site-packages/flask/app.py", line 1612, in full_dispatch_request
    rv = self.dispatch_request()
  File "/home/ari/Documents/LastChance/microblog/mb_venv/lib/python3.5/site-packages/flask/app.py", line 1598, in dispatch_request
    return self.view_functions[rule.endpoint](**req.view_args)
  File "/home/ari/Documents/LastChance/microblog/mb_venv/lib/python3.5/site-packages/flask_login/utils.py", line 261, in decorated_view
    return func(*args, **kwargs)
  File "/home/ari/Documents/LastChance/microblog/app/routes.py", line 81, in index
    posts = posts.items, next_url=next_url, prev_url=prev_url)
AttributeError: 'list' object has no attribute 'items'
2018-03-27 05:06:43,136 INFO: Microblog startup [in /home/ari/Documents/LastChance/microblog/app/__init__.py: 49]
2018-03-27 05:07:19,812 ERROR: Exception on /index [GET] [in /home/ari/Documents/LastChance/microblog/mb_venv/lib/python3.5/site-packages/flask/app.py: 1560]
Traceback (most recent call last):
  File "/home/ari/Documents/LastChance/microblog/mb_venv/lib/python3.5/site-packages/flask/app.py", line 1982, in wsgi_app
    response = self.full_dispatch_request()
  File "/home/ari/Documents/LastChance/microblog/mb_venv/lib/python3.5/site-packages/flask/app.py", line 1614, in full_dispatch_request
    rv = self.handle_user_exception(e)
  File "/home/ari/Documents/LastChance/microblog/mb_venv/lib/python3.5/site-packages/flask/app.py", line 1517, in handle_user_exception
    reraise(exc_type, exc_value, tb)
  File "/home/ari/Documents/LastChance/microblog/mb_venv/lib/python3.5/site-packages/flask/_compat.py", line 33, in reraise
    raise value
  File "/home/ari/Documents/LastChance/microblog/mb_venv/lib/python3.5/site-packages/flask/app.py", line 1612, in full_dispatch_request
    rv = self.dispatch_request()
  File "/home/ari/Documents/LastChance/microblog/mb_venv/lib/python3.5/site-packages/flask/app.py", line 1598, in dispatch_request
    return self.view_functions[rule.endpoint](**req.view_args)
  File "/home/ari/Documents/LastChance/microblog/mb_venv/lib/python3.5/site-packages/flask_login/utils.py", line 261, in decorated_view
    return func(*args, **kwargs)
  File "/home/ari/Documents/LastChance/microblog/app/routes.py", line 81, in index
    posts = posts.items, next_url=next_url, prev_url=prev_url)
AttributeError: 'list' object has no attribute 'items'
2018-03-27 05:08:26,672 ERROR: Exception on /index [GET] [in /home/ari/Documents/LastChance/microblog/mb_venv/lib/python3.5/site-packages/flask/app.py: 1560]
Traceback (most recent call last):
  File "/home/ari/Documents/LastChance/microblog/mb_venv/lib/python3.5/site-packages/flask/app.py", line 1982, in wsgi_app
    response = self.full_dispatch_request()
  File "/home/ari/Documents/LastChance/microblog/mb_venv/lib/python3.5/site-packages/flask/app.py", line 1614, in full_dispatch_request
    rv = self.handle_user_exception(e)
  File "/home/ari/Documents/LastChance/microblog/mb_venv/lib/python3.5/site-packages/flask/app.py", line 1517, in handle_user_exception
    reraise(exc_type, exc_value, tb)
  File "/home/ari/Documents/LastChance/microblog/mb_venv/lib/python3.5/site-packages/flask/_compat.py", line 33, in reraise
    raise value
  File "/home/ari/Documents/LastChance/microblog/mb_venv/lib/python3.5/site-packages/flask/app.py", line 1612, in full_dispatch_request
    rv = self.dispatch_request()
  File "/home/ari/Documents/LastChance/microblog/mb_venv/lib/python3.5/site-packages/flask/app.py", line 1598, in dispatch_request
    return self.view_functions[rule.endpoint](**req.view_args)
  File "/home/ari/Documents/LastChance/microblog/mb_venv/lib/python3.5/site-packages/flask_login/utils.py", line 261, in decorated_view
    return func(*args, **kwargs)
  File "/home/ari/Documents/LastChance/microblog/app/routes.py", line 81, in index
    posts = posts.items, next_url=next_url, prev_url=prev_url)
AttributeError: 'list' object has no attribute 'items'
2018-03-28 00:02:35,149 INFO: Microblog startup [in /home/ari/Documents/LastChance/microblog/app/__init__.py: 49]
2018-03-28 00:09:57,483 INFO: Microblog startup [in /home/ari/Documents/LastChance/microblog/app/__init__.py: 49]
